Failure # 1 (occurred at 2023-12-02_17-38-25)
The actor died because of an error raised in its creation task, [36mray::PPO.__init__()[39m (pid=38738, ip=127.0.0.1, actor_id=d5b920c641da8a2b103a84da01000000, repr=PPO)
  File "/Users/hongjihye/anaconda3/lib/python3.11/site-packages/ray/rllib/evaluation/worker_set.py", line 227, in _setup
    self.add_workers(
  File "/Users/hongjihye/anaconda3/lib/python3.11/site-packages/ray/rllib/evaluation/worker_set.py", line 593, in add_workers
    raise result.get()
  File "/Users/hongjihye/anaconda3/lib/python3.11/site-packages/ray/rllib/utils/actor_manager.py", line 481, in __fetch_result
    result = ray.get(r)
             ^^^^^^^^^^
           ^^^^^^^^^^^^^^^^^^^
           ^^^^^^^^^^^^^^^^^^^^^
ray.exceptions.RayActorError: The actor died because of an error raised in its creation task, [36mray::RolloutWorker.__init__()[39m (pid=38759, ip=127.0.0.1, actor_id=fcc8f2fef695ad758d973b6101000000, repr=<ray.rllib.evaluation.rollout_worker.RolloutWorker object at 0x13ed9fbd0>)
  File "/Users/hongjihye/anaconda3/lib/python3.11/site-packages/ray/rllib/utils/pre_checks/env.py", line 155, in check_gym_environments
    raise ValueError("Observation space must be a gymnasium.Space!")
ValueError: Observation space must be a gymnasium.Space!

During handling of the above exception, another exception occurred:

[36mray::RolloutWorker.__init__()[39m (pid=38759, ip=127.0.0.1, actor_id=fcc8f2fef695ad758d973b6101000000, repr=<ray.rllib.evaluation.rollout_worker.RolloutWorker object at 0x13ed9fbd0>)
           ^^^^^^^^^^^^^^^^^^^^^^^^^^^^^^^^^^^^
           ^^^^^^^^^^^^^^^^^^^^^^^^^^^^^^^
  File "/Users/hongjihye/anaconda3/lib/python3.11/site-packages/ray/rllib/evaluation/rollout_worker.py", line 404, in __init__
    check_env(self.env, self.config)
  File "/Users/hongjihye/anaconda3/lib/python3.11/site-packages/ray/rllib/utils/pre_checks/env.py", line 96, in check_env
    raise ValueError(
ValueError: Traceback (most recent call last):
  File "/Users/hongjihye/anaconda3/lib/python3.11/site-packages/ray/rllib/utils/pre_checks/env.py", line 85, in check_env
    check_gym_environments(env, AlgorithmConfig() if config is None else config)
  File "/Users/hongjihye/anaconda3/lib/python3.11/site-packages/ray/rllib/utils/pre_checks/env.py", line 155, in check_gym_environments
    raise ValueError("Observation space must be a gymnasium.Space!")
ValueError: Observation space must be a gymnasium.Space!

The above error has been found in your environment! We've added a module for checking your custom environments. It may cause your experiment to fail if your environment is not set up correctly. You can disable this behavior via calling `config.environment(disable_env_checking=True)`. You can run the environment checking module standalone by calling ray.rllib.utils.check_env([your env]).

During handling of the above exception, another exception occurred:

[36mray::PPO.__init__()[39m (pid=38738, ip=127.0.0.1, actor_id=d5b920c641da8a2b103a84da01000000, repr=PPO)
           ^^^^^^^^^^^^^^^^^^^^^^^^^^^^^^^^^^^^
           ^^^^^^^^^^^^^^^^^^^^^^^^^^^^^^^
  File "/Users/hongjihye/anaconda3/lib/python3.11/site-packages/ray/rllib/algorithms/algorithm.py", line 517, in __init__
    super().__init__(
  File "/Users/hongjihye/anaconda3/lib/python3.11/site-packages/ray/tune/trainable/trainable.py", line 161, in __init__
    self.setup(copy.deepcopy(self.config))
           ^^^^^^^^^^^^^^^^^^^^^^^^^^^^^^^
  File "/Users/hongjihye/anaconda3/lib/python3.11/site-packages/ray/rllib/algorithms/algorithm.py", line 639, in setup
    self.workers = WorkerSet(
                   ^^^^^^^^^^
  File "/Users/hongjihye/anaconda3/lib/python3.11/site-packages/ray/rllib/evaluation/worker_set.py", line 179, in __init__
    raise e.args[0].args[2]
ValueError: Traceback (most recent call last):
  File "/Users/hongjihye/anaconda3/lib/python3.11/site-packages/ray/rllib/utils/pre_checks/env.py", line 85, in check_env
    check_gym_environments(env, AlgorithmConfig() if config is None else config)
  File "/Users/hongjihye/anaconda3/lib/python3.11/site-packages/ray/rllib/utils/pre_checks/env.py", line 155, in check_gym_environments
    raise ValueError("Observation space must be a gymnasium.Space!")
ValueError: Observation space must be a gymnasium.Space!

The above error has been found in your environment! We've added a module for checking your custom environments. It may cause your experiment to fail if your environment is not set up correctly. You can disable this behavior via calling `config.environment(disable_env_checking=True)`. You can run the environment checking module standalone by calling ray.rllib.utils.check_env([your env]).
